"use client"

import React from "react"
import { AlertTriangle, RefreshCw } from "lucide-react"
import { Button } from "@/components/ui/button"
import { Card, CardContent, CardDescription, CardHeader, CardTitle } from "@/components/ui/card"

interface ErrorBoundaryProps {
  children: React.ReactNode
  fallback?: React.ReactNode
}

interface ErrorBoundaryState {
  hasError: boolean
  error: Error | null
}

export class ErrorBoundary extends React.Component<ErrorBoundaryProps, ErrorBoundaryState> {
  constructor(props: ErrorBoundaryProps) {
    super(props)
    this.state = { hasError: false, error: null }
  }

  static getDerivedStateFromError(error: Error): ErrorBoundaryState {
    return { hasError: true, error }
  }

  componentDidCatch(error: Error, errorInfo: React.ErrorInfo) {
    console.error("Error caught by boundary:", error, errorInfo)
  }

  render() {
    if (this.state.hasError) {
      if (this.props.fallback) {
        return this.props.fallback
      }

      return (
        <Card className="w-full max-w-md mx-auto mt-8">
          <CardHeader>
            <div className="flex items-center space-x-2">
              <AlertTriangle className="h-5 w-5 text-red-500" />
              <CardTitle className="text-red-700">Something went wrong</CardTitle>
            </div>
            <CardDescription>{this.state.error?.message || "An unexpected error occurred"}</CardDescription>
          </CardHeader>
          <CardContent>
            <Button
              onClick={() => this.setState({ hasError: false, error: null })}
              className="w-full"
              variant="outline"
            >
              <RefreshCw className="h-4 w-4 mr-2" />
              Try again
            </Button>
          </CardContent>
        </Card>
      )
    }

    return this.props.children
  }
}

// Hook version for functional components
export function useErrorHandler() {
  const [error, setError] = React.useState<Error | null>(null)

  const resetError = () => setError(null)

  const handleError = (error: Error) => {
    console.error("Error handled:", error)
    setError(error)
  }

  if (error) {
    throw error // This will be caught by ErrorBoundary
  }

  return { handleError, resetError }
}
